<?xml version="1.0"?>
<robot name="simple_robot">
  <!-- Base Link -->
  <link name="base_link">
    <visual>
      <geometry>
        <box size="0.3 0.3 0.1"/>
      </geometry>
      <material name="blue">
        <color rgba="0 0 0.8 1"/>
      </material>
    </visual>
    <collision>
      <geometry>
        <box size="0.3 0.3 0.1"/>
      </geometry>
    </collision>
    <inertial>
      <mass value="1.0"/>
      <origin xyz="0 0 0" rpy="0 0 0"/>
      <inertia ixx="0.01" ixy="0.0" ixz="0.0" iyy="0.01" iyz="0.0" izz="0.01"/>
    </inertial>
  </link>

  <!-- Right Wheel -->
  <link name="right_wheel">
    <visual>
      <geometry>
        <cylinder radius="0.06" length="0.04"/>
      </geometry>
      <material name="black">
        <color rgba="0 0 0 1"/>
      </material>
      <origin xyz="0 0 0" rpy="1.5707 0 0"/>
    </visual>
    <collision>
      <geometry>
        <cylinder radius="0.06" length="0.04"/>
      </geometry>
      <origin xyz="0 0 0" rpy="1.5707 0 0"/>
    </collision>
    <inertial>
      <mass value="0.1"/>
      <origin xyz="0 0 0" rpy="1.5707 0 0"/>
      <inertia ixx="0.00015" ixy="0.0" ixz="0.0" iyy="0.00015" iyz="0.0" izz="0.0001"/>
    </inertial>
  </link>

  <!-- Left Wheel -->
  <link name="left_wheel">
    <visual>
      <geometry>
        <cylinder radius="0.06" length="0.04"/>
      </geometry>
      <material name="black">
        <color rgba="0 0 0 1"/>
      </material>
      <origin xyz="0 0 0" rpy="1.5707 0 0"/>
    </visual>
    <collision>
      <geometry>
        <cylinder radius="0.06" length="0.04"/>
      </geometry>
      <origin xyz="0 0 0" rpy="1.5707 0 0"/>
    </collision>
    <inertial>
      <mass value="0.1"/>
      <origin xyz="0 0 0" rpy="1.5707 0 0"/>
      <inertia ixx="0.00015" ixy="0.0" ixz="0.0" iyy="0.00015" iyz="0.0" izz="0.0001"/>
    </inertial>
  </link>

  <!-- Caster Wheel -->
  <link name="caster_wheel">
    <visual>
      <geometry>
        <sphere radius="0.03"/>
      </geometry>
      <material name="grey">
        <color rgba="0.5 0.5 0.5 1"/>
      </material>
    </visual>
    <collision>
      <geometry>
        <sphere radius="0.03"/>
      </geometry>
    </collision>
    <inertial>
      <mass value="0.05"/>
      <origin xyz="0.1 0 0" rpy="0 0 0"/>
      <inertia ixx="0.00002" ixy="0.0" ixz="0.0" iyy="0.00002" iyz="0.0" izz="0.00002"/>
    </inertial>
  </link>

  <!-- Right Wheel Joint -->
  <joint name="right_wheel_joint" type="revolute">
    <parent link="base_link"/>
    <child link="right_wheel"/>
    <origin xyz="-0.05 -0.17 0" rpy="0 0 0"/>
    <axis xyz="0 1 0"/>
    <limit lower="-1.79769e+308" upper="1.79769e+308" effort="100" velocity="100"/>
    <dynamics damping="0.01" friction="0.0"/>
  </joint>

  <!-- Left Wheel Joint -->
  <joint name="left_wheel_joint" type="revolute">
    <parent link="base_link"/>
    <child link="left_wheel"/>
    <origin xyz="-0.05 0.17 0" rpy="0 0 0"/>
    <axis xyz="0 1 0"/>
    <limit lower="-1.79769e+308" upper="1.79769e+308" effort="100" velocity="100"/>
    <dynamics damping="0.01" friction="0.0"/>
  </joint>

  <!-- Caster Joint -->
  <joint name="caster_joint" type="fixed">
    <parent link="base_link"/>
    <child link="caster_wheel"/>
    <origin xyz="0.12 0 -0.0325" rpy="0 0 0"/>
  </joint>

  <!-- Camera Link -->
  <link name="camera_link">
    <visual>
      <geometry>
        <box size="0.03 0.03 0.03"/>
      </geometry>
      <material name="red">
        <color rgba="1 0 0 1"/>
      </material>
    </visual>
    <collision>
      <geometry>
        <box size="0.01 0.01 0.01"/>
      </geometry>
    </collision>
    <inertial>
      <mass value="0.01"/>
      <origin xyz="0 0 0" rpy="0 0 0"/>
      <inertia ixx="0.0001" ixy="0.0" ixz="0.0" iyy="0.0001" iyz="0.0" izz="0.0001"/>
    </inertial>
  </link>

  <!-- Camera Joint -->
  <joint name="camera_joint" type="fixed">
    <parent link="base_link"/>
    <child link="camera_link"/>
    <origin xyz="0.15 0 0.055" rpy="0 0 0"/>
  </joint>

  <!-- Camera Optical Link -->
  <link name="camera_link_optical">
    <inertial>
      <mass value="0.001"/>
      <origin xyz="0 0 0" rpy="0 0 0"/>
      <inertia ixx="0.00001" ixy="0.0" ixz="0.0" iyy="0.00001" iyz="0.0" izz="0.00001"/>
    </inertial>
  </link>

  <!-- Camera Optical Joint -->
  <joint name="camera_optical_joint" type="fixed">
    <parent link="camera_link"/>
    <child link="camera_link_optical"/>
    <origin xyz="0 0 0" rpy="-1.5707 0 -1.5707"/>
  </joint>
</robot>
